Traceback (most recent call last):
  File "C:\Users\user\AppData\Local\Programs\Python\Python313\Lib\site-packages\httpx\_transports\default.py", line 101, in map_httpcore_exceptions
    yield
  File "C:\Users\user\AppData\Local\Programs\Python\Python313\Lib\site-packages\httpx\_transports\default.py", line 394, in handle_async_request
    resp = await self._pool.handle_async_request(req)
           ^^^^^^^^^^^^^^^^^^^^^^^^^^^^^^^^^^^^^^^^^^
  File "C:\Users\user\AppData\Local\Programs\Python\Python313\Lib\site-packages\httpcore\_async\connection_pool.py", line 256, in handle_async_request
    raise exc from None
  File "C:\Users\user\AppData\Local\Programs\Python\Python313\Lib\site-packages\httpcore\_async\connection_pool.py", line 236, in handle_async_request
    response = await connection.handle_async_request(
               ^^^^^^^^^^^^^^^^^^^^^^^^^^^^^^^^^^^^^^
        pool_request.request
        ^^^^^^^^^^^^^^^^^^^^
    )
    ^
  File "C:\Users\user\AppData\Local\Programs\Python\Python313\Lib\site-packages\httpcore\_async\connection.py", line 103, in handle_async_request
    return await self._connection.handle_async_request(request)
           ^^^^^^^^^^^^^^^^^^^^^^^^^^^^^^^^^^^^^^^^^^^^^^^^^^^^
  File "C:\Users\user\AppData\Local\Programs\Python\Python313\Lib\site-packages\httpcore\_async\http11.py", line 136, in handle_async_request
    raise exc
  File "C:\Users\user\AppData\Local\Programs\Python\Python313\Lib\site-packages\httpcore\_async\http11.py", line 106, in handle_async_request
    ) = await self._receive_response_headers(**kwargs)
        ^^^^^^^^^^^^^^^^^^^^^^^^^^^^^^^^^^^^^^^^^^^^^^
  File "C:\Users\user\AppData\Local\Programs\Python\Python313\Lib\site-packages\httpcore\_async\http11.py", line 177, in _receive_response_headers
    event = await self._receive_event(timeout=timeout)
            ^^^^^^^^^^^^^^^^^^^^^^^^^^^^^^^^^^^^^^^^^^
  File "C:\Users\user\AppData\Local\Programs\Python\Python313\Lib\site-packages\httpcore\_async\http11.py", line 217, in _receive_event
    data = await self._network_stream.read(
           ^^^^^^^^^^^^^^^^^^^^^^^^^^^^^^^^
        self.READ_NUM_BYTES, timeout=timeout
        ^^^^^^^^^^^^^^^^^^^^^^^^^^^^^^^^^^^^
    )
    ^
  File "C:\Users\user\AppData\Local\Programs\Python\Python313\Lib\site-packages\httpcore\_backends\anyio.py", line 32, in read
    with map_exceptions(exc_map):
         ~~~~~~~~~~~~~~^^^^^^^^^
  File "C:\Users\user\AppData\Local\Programs\Python\Python313\Lib\contextlib.py", line 162, in __exit__
    self.gen.throw(value)
    ~~~~~~~~~~~~~~^^^^^^^
  File "C:\Users\user\AppData\Local\Programs\Python\Python313\Lib\site-packages\httpcore\_exceptions.py", line 14, in map_exceptions
    raise to_exc(exc) from exc
httpcore.ReadTimeout

The above exception was the direct cause of the following exception:

Traceback (most recent call last):
  File "C:\Users\user\AppData\Local\Programs\Python\Python313\Lib\site-packages\telegram\request\_httpxrequest.py", line 292, in do_request
    res = await self._client.request(
          ^^^^^^^^^^^^^^^^^^^^^^^^^^^
    ...<6 lines>...
    )
    ^
  File "C:\Users\user\AppData\Local\Programs\Python\Python313\Lib\site-packages\httpx\_client.py", line 1540, in request
    return await self.send(request, auth=auth, follow_redirects=follow_redirects)
           ^^^^^^^^^^^^^^^^^^^^^^^^^^^^^^^^^^^^^^^^^^^^^^^^^^^^^^^^^^^^^^^^^^^^^^
  File "C:\Users\user\AppData\Local\Programs\Python\Python313\Lib\site-packages\httpx\_client.py", line 1629, in send
    response = await self._send_handling_auth(
               ^^^^^^^^^^^^^^^^^^^^^^^^^^^^^^^
    ...<4 lines>...
    )
    ^
  File "C:\Users\user\AppData\Local\Programs\Python\Python313\Lib\site-packages\httpx\_client.py", line 1657, in _send_handling_auth
    response = await self._send_handling_redirects(
               ^^^^^^^^^^^^^^^^^^^^^^^^^^^^^^^^^^^^
    ...<3 lines>...
    )
    ^
  File "C:\Users\user\AppData\Local\Programs\Python\Python313\Lib\site-packages\httpx\_client.py", line 1694, in _send_handling_redirects
    response = await self._send_single_request(request)
               ^^^^^^^^^^^^^^^^^^^^^^^^^^^^^^^^^^^^^^^^
  File "C:\Users\user\AppData\Local\Programs\Python\Python313\Lib\site-packages\httpx\_client.py", line 1730, in _send_single_request
    response = await transport.handle_async_request(request)
               ^^^^^^^^^^^^^^^^^^^^^^^^^^^^^^^^^^^^^^^^^^^^^
  File "C:\Users\user\AppData\Local\Programs\Python\Python313\Lib\site-packages\httpx\_transports\default.py", line 393, in handle_async_request
    with map_httpcore_exceptions():
         ~~~~~~~~~~~~~~~~~~~~~~~^^
  File "C:\Users\user\AppData\Local\Programs\Python\Python313\Lib\contextlib.py", line 162, in __exit__
    self.gen.throw(value)
    ~~~~~~~~~~~~~~^^^^^^^
  File "C:\Users\user\AppData\Local\Programs\Python\Python313\Lib\site-packages\httpx\_transports\default.py", line 118, in map_httpcore_exceptions
    raise mapped_exc(message) from exc
httpx.ReadTimeout

The above exception was the direct cause of the following exception:

Traceback (most recent call last):
  File "C:\Users\user\AppData\Local\Programs\Python\Python313\Lib\site-packages\telegram\ext\_application.py", line 1335, in process_update
    await coroutine
  File "C:\Users\user\AppData\Local\Programs\Python\Python313\Lib\site-packages\telegram\ext\_handlers\basehandler.py", line 158, in handle_update
    return await self.callback(update, context)
           ^^^^^^^^^^^^^^^^^^^^^^^^^^^^^^^^^^^^
  File "D:\my cods\папка 5\MyChassBot_SheetsExample\MyChassBot_SheetsExample_5_and-tk_and-wan_orOogg.py", line 241, in tg_handle_voice
    await file.download_to_drive(ogg_path)
  File "C:\Users\user\AppData\Local\Programs\Python\Python313\Lib\site-packages\telegram\_files\file.py", line 206, in download_to_drive
    buf = await self.get_bot().request.retrieve(
          ^^^^^^^^^^^^^^^^^^^^^^^^^^^^^^^^^^^^^^
    ...<5 lines>...
    )
    ^
  File "C:\Users\user\AppData\Local\Programs\Python\Python313\Lib\site-packages\telegram\request\_baserequest.py", line 253, in retrieve
    return await self._request_wrapper(
           ^^^^^^^^^^^^^^^^^^^^^^^^^^^^
    ...<6 lines>...
    )
    ^
  File "C:\Users\user\AppData\Local\Programs\Python\Python313\Lib\site-packages\telegram\request\_baserequest.py", line 333, in _request_wrapper
    code, payload = await self.do_request(
                    ^^^^^^^^^^^^^^^^^^^^^^
    ...<7 lines>...
    )
    ^
  File "C:\Users\user\AppData\Local\Programs\Python\Python313\Lib\site-packages\telegram\request\_httpxrequest.py", line 309, in do_request
    raise TimedOut from err
telegram.error.TimedOut: Timed out
